Workbook

Sheet Vorlage
B2: Kommissioniersystem
B4: Linke Seite
B6: Blue Wedge 2 x 1 x 2/3 Left | E6: Blue Tile, Modified Facet 2 x 2 | H6: Blue Slope, Curved 4 x 1 x 2/3 Double | K6: Blue Slope, Curved 4 x 1 | N6: Blue Slope, Curved 2 x 1 x 2/3 | Q6: Blue Plate 1 x 2 | T6: Blue Brick, Modified 1 x 1 with Headlight
B7: #VALUE! | C7: Nr. | D7: 6172414 | E7: #VALUE! | F7: Nr. | G7: 6333512 | H7: #VALUE! | I7: Nr. | J7: 4649773 | K7: #VALUE! | L7: Nr. | M7: 6045938 | N7: #VALUE! | O7: Nr. | P7: 6055065 | Q7: #VALUE! | R7: Nr. | S7: 302323 | T7: #VALUE! | U7: Nr. | V7: 407023
C8: Gewicht | D8: 0.2242 | F8: Gewicht | G8: 0.3504 | I8: Gewicht | J8: 0.589 | L8: Gewicht | M8: 0.7661 | O8: Gewicht | P8: 0.306 | R8: Gewicht | S8: 0.334 | U8: Gewicht | V8: 0.3406
C9: Anzahl | D9: 0 | F9: Anzahl | G9: 0 | I9: Anzahl | J9: 0 | L9: Anzahl | M9: 0 | O9: Anzahl | P9: 0 | R9: Anzahl | S9: 0 | U9: Anzahl | V9: 0
B11: Trans-Clear Slope 30 1 x 1 x 2/3 | E11: Black Plate, Round 1 x 1 | H11: Blue Slope 30 1 x 1 x 2/3 | K11: Blue Tile, Round 1 x 1 Quarter | N11: Black Tile 1 x 1 with Groove | Q11: Part 36841 Bracket 1 x 1 - 1 x 1 | T11: Blue Plate 2 x 2 Corner
B12: #VALUE! | C12: Nr. | D12: 6245250 | E12: #VALUE! | F12: Nr. | G12: 614126 | H12: #VALUE! | I12: Nr. | J12: 4296154 | K12: #VALUE! | L12: Nr. | M12: 6302961 | N12: #VALUE! | O12: Nr. | P12: 307026 | Q12: #VALUE! | R12: Nr. | S12: 6299338 | T12: #VALUE! | U12: Nr. | V12: 242023
C13: Gewicht | D13: 0.2116 | F13: Gewicht | G13: 0.1083 | I13: Gewicht | J13: 0.1835 | L13: Gewicht | M13: 0.1066 | O13: Gewicht | P13: 0.1436 | R13: Gewicht | S13: 0.2834 | U13: Gewicht | V13: 0.4974
C14: Anzahl | D14: 0 | F14: Anzahl | G14: 0 | I14: Anzahl | J14: 0 | L14: Anzahl | M14: 0 | O14: Anzahl | P14: 0 | R14: Anzahl | S14: 0 | U14: Anzahl | V14: 0
B16: White Plate 1 x 2 | E16: White Plate 2 x 3 | H16: Yellow Plate, Round 1 x 1 | K16: Light Bluish Gray Plate, Modified with Wheel Holder | N16: Black Bracket 1 x 2 - 1 x 2 | Q16: Black Plate 3 x 3 | T16: Blue Slope 30 1 x 2 x 2/3
B17: #VALUE! | C17: Nr. | D17: 302301 | E17: #VALUE! | F17: Nr. | G17: 302101 | H17: #VALUE! | I17: Nr. | J17: 614124 | K17: #VALUE! | L17: Nr. | M17: 6125569 | N17: #VALUE! | O17: Nr. | P17: 6016172 | Q17: #VALUE! | R17: Nr. | S17: 6174917 | T17: #VALUE! | U17: Nr. | V17: 4651236
C18: Gewicht | D18: 0.3367 | F18: Gewicht | G18: 0.8767 | I18: Gewicht | J18: 0.1088 | L18: Gewicht | M18: 0.4478 | O18: Gewicht | P18: 0.5403 | R18: Gewicht | S18: 1.2561 | U18: Gewicht | V18: 0.2736
C19: Anzahl | D19: 0 | F19: Anzahl | G19: 0 | I19: Anzahl | J19: 0 | L19: Anzahl | M19: 0 | O19: Anzahl | P19: 0 | R19: Anzahl | S19: 0 | U19: Anzahl | V19: 0
B21: Red Bracket 1 x 2 - 1 x 4 with Two Rounded Corners at the Bottom | E21: Trans-Red Tile, Modified 1 x 2 Grille with Bottom Groove / Lip | H21: Red Tile, Round 1 x 1 Quarter | K21: Red Tile, Modified 2 x 2 with Studs on Edge | N21: Red Slope, Curved 2 x 1 x 2/3 | Q21: Red Slope 45 2 x 1 with 2/3 Cutout | T21: Red Plate 1 x 4
B22: #VALUE! | C22: Nr. | D22: 6168619 | E22: #VALUE! | F22: Nr. | G22: 6250158 | H22: #VALUE! | I22: Nr. | J22: 6170390 | K22: #VALUE! | L22: Nr. | M22: 6219819 | N22: #VALUE! | O22: Nr. | P22: 6029946 | Q22: #VALUE! | R22: Nr. | S22: 6053011 | T22: #VALUE! | U22: Nr. | V22: 371021
C23: Gewicht | D23: 0.7817 | F23: Gewicht | G23: 0.2397 | I23: Gewicht | J23: 0.1071 | L23: Gewicht | M23: 0.5492 | O23: Gewicht | P23: 0.3011 | R23: Gewicht | S23: 0.4087 | U23: Gewicht | V23: 0.6503
C24: Anzahl | D24: 0 | F24: Anzahl | G24: 0 | I24: Anzahl | J24: 0 | L24: Anzahl | M24: 0 | O24: Anzahl | P24: 0 | R24: Anzahl | S24: 0 | U24: Anzahl | V24: 0
B26: White Tile, Round 1 x 1 Half Circle Extended | E26: Light Bluish Gray Tile 1 x 1 with Groove | H26: Blue Wedge, Plate 2 x 2 Right | K26: Blue Wedge, Plate 2 x 2 Left | N26: Blue Tile 2 x 2 with Groove | Q26: Red Plate 1 x 2 | T26: Blue Wedge 2 x 1 x 2/3 Right
B27: #VALUE! | C27: Nr. | D27: 6131655 | E27: #VALUE! | F27: Nr. | G27: 4211415 | H27: #VALUE! | I27: Nr. | J27: 6189202 | K27: #VALUE! | L27: Nr. | M27: 6189198 | N27: #VALUE! | O27: Nr. | P27: 306823 | Q27: #VALUE! | R27: Nr. | S27: 302321 | T27: #VALUE! | U27: Nr. | V27: 6172411
C28: Gewicht | D28: 0.1257 | F28: Gewicht | G28: 0.1418 | I28: Gewicht | J28: 0.4511 | L28: Gewicht | M28: 0.4535 | O28: Gewicht | P28: 0.4796 | R28: Gewicht | S28: 0.3331 | U28: Gewicht | V28: 0.2242
C29: Anzahl | D29: 0 | F29: Anzahl | G29: 0 | I29: Anzahl | J29: 0 | L29: Anzahl | M29: 0 | O29: Anzahl | P29: 0 | R29: Anzahl | S29: 0 | U29: Anzahl | V29: 0
B31: Blue Tile 1 x 2 with Groove | E31: Blue Plate 1 x 10 | H31: Black Tile, Modified 1 x 2 Grille with Bottom Groove / Lip | K31: Black Tile, 1 x 4 | N31: Red Slope, Curved 4 x 2 | Q31: Red Vehicla, Mudguard 2 x 4 with Arch Studded with Hole | T31: Red Wedge 3 x 4 x 2/3 Curved with Cutout
B32: #VALUE! | C32: Nr. | D32: 306923 | E32: #VALUE! | F32: Nr. | G32: 447723 | H32: #VALUE! | I32: Nr. | J32: 241226 | K32: #VALUE! | L32: Nr. | M32: 243126 | N32: #VALUE! | O32: Nr. | P32: 4613174 | Q32: #VALUE! | R32: Nr. | S32: 4518231 | T32: #VALUE! | U32: Nr. | V32: 6179656
C33: Gewicht | D33: 0.2575 | F33: Gewicht | G33: 1.6056 | I33: Gewicht | J33: 0.2158 | L33: Gewicht | M33: 0.5271 | O33: Gewicht | P33: 1.3333 | R33: Gewicht | S33: 1.3094 | U33: Gewicht | V33: 1.4239
C34: Anzahl | D34: 0 | F34: Anzahl | G34: 0 | I34: Anzahl | J34: 0 | L34: Anzahl | M34: 0 | O34: Anzahl | P34: 0 | R34: Anzahl | S34: 0 | U34: Anzahl | V34: 0
B36: Lagerbock 100-000-001 | E36: Sicherungsring DIN 471 - 1,0 x 1,0 | H36: Sicherungsring DIN 472 - 30 x 1,2 | K36: Rillenkugellager DIN 625 - 6200 - P2 | N36: Gewindestift ISO 4027 - M4 x 6 - A5 - 45H | Q36: Black Plate 2 x 3 | T36: Black Brick, Modified 1 x 1 with Stud on Side
B37: #VALUE! | C37: Nr. | D37: L007001 | E37: #VALUE! | F37: Nr. | G37: L007002 | H37: #VALUE! | I37: Nr. | J37: L007003 | K37: #VALUE! | L37: Nr. | M37: L007004 | N37: #VALUE! | O37: Nr. | P37: L007005 | Q37: #VALUE! | R37: Nr. | S37: 302126 | T37: #VALUE! | U37: Nr. | V37: 4558954
C38: Gewicht | D38: 8.88 | F38: Gewicht | G38: 0.405 | I38: Gewicht | J38: 1.9188 | L38: Gewicht | M38: 30.775 | O38: Gewicht | P38: 0.2825 | R38: Gewicht | S38: 0.8589 | U38: Gewicht | V38: 0.4278
C39: Anzahl | D39: 0 | F39: Anzahl | G39: 0 | I39: Anzahl | J39: 0 | L39: Anzahl | M39: 0 | O39: Anzahl | P39: 0 | R39: Anzahl | S39: 0 | U39: Anzahl | V39: 0
B42: Rechte Seite
B44: Black Bracket 1 x 2 - 1 x 4 with Two Rounded Corners at the Bottom | E44: Black Bracket 1 x 2 - 2 x 2 | H44: Black Plate 1 x 1 | K44: Part 54200 Slope 30 1 x 1 x 2/3 | N44: Dark Orange Plate Round 1 x 1 | Q44: Black Panel 1 x 1 x 1 Corner | T44: Red Plate 1 x 1
B45: #VALUE! | C45: Nr. | D45: 6168620 | E45: #VALUE! | F45: Nr. | G45: 6117973 | H45: #VALUE! | I45: Nr. | J45: 302426 | K45: #VALUE! | L45: Nr. | M45: 4287159 | N45: #VALUE! | O45: Nr. | P45: 6315782 | Q45: #VALUE! | R45: Nr. | S45: 4106347 | T45: #VALUE! | U45: Nr. | V45: 302421
C46: Gewicht | D46: 0.7731 | F46: Gewicht | G46: 0.7924 | I46: Gewicht | J46: 0.1745 | L46: Gewicht | M46: 0.1848 | O46: Gewicht | P46: 0.1043 | R46: Gewicht | S46: 0.2889 | U46: Gewicht | V46: 0.175
C47: Anzahl | D47: 0 | F47: Anzahl | G47: 0 | I47: Anzahl | J47: 0 | L47: Anzahl | M47: 0 | O47: Anzahl | P47: 0 | R47: Anzahl | S47: 0 | U47: Anzahl | V47: 0
B49: Black Wheel 11mm 0. x 6mm with 8 'Y' Spokes | E49: Red Slope 30 1 x 2 x 2/3 | H49: Black Plate 1 x 4 | K49: Black Slope 30 1 x 2 x 2/3 | N49: Black Bracket 1 x 2 - 2 x 4 | Q49: Nougat Plate 2 x 4 | T49: Black Wedge, Plate 2 x 2 Right
B50: #VALUE! | C50: Nr. | D50: 4613162 | E50: #VALUE! | F50: Nr. | G50: 4651524 | H50: #VALUE! | I50: Nr. | J50: 371026 | K50: #VALUE! | L50: Nr. | M50: 4548180 | N50: #VALUE! | O50: Nr. | P50: 6118829 | Q50: #VALUE! | R50: Nr. | S50: 4497049 | T50: #VALUE! | U50: Nr. | V50: 6141556
C51: Gewicht | D51: 0.3292 | F51: Gewicht | G51: 0.3408 | I51: Gewicht | J51: 0.6427 | L51: Gewicht | M51: 0.3507 | O51: Gewicht | P51: 1.2711 | R51: Gewicht | S51: 1.1502 | U51: Gewicht | V51: 0.45
C52: Anzahl | D52: 0 | F52: Anzahl | G52: 0 | I52: Anzahl | J52: 0 | L52: Anzahl | M52: 0 | O52: Anzahl | P52: 0 | R52: Anzahl | S52: 0 | U52: Anzahl | V52: 0
B54: Black Tire 14mm 0. x 6mm Solid Smooth | E54: Black Tile, Modified 2 x 2 with Studs on Edge | H54: Metallic Gold Tile 1 x 2 with Groove | K54: Black Tile 1 x 3 | N54: Black Plate 2 x 6 | Q54: Black Slope, Curved 2 x 1 x 2/3 | T54: White Bracket 1 x 2 - 1 x 4 with Two Rounded Corners at the Bottom
...

Sheet Muscle_Car
B2: Kommissioniersystem
B4: Linke Seite
B6: Blue Wedge 2 x 1 x 2/3 Left | E6: Blue Tile, Modified Facet 2 x 2 | H6: Blue Slope, Curved 4 x 1 x 2/3 Double | K6: Blue Slope, Curved 4 x 1 | N6: Blue Slope, Curved 2 x 1 x 2/3 | Q6: Blue Plate 1 x 2 | T6: Blue Brick, Modified 1 x 1 with Headlight
B7: #VALUE! | C7: Nr. | D7: 6172414 | E7: #VALUE! | F7: Nr. | G7: 6333512 | H7: #VALUE! | I7: Nr. | J7: 4649773 | K7: #VALUE! | L7: Nr. | M7: 6045938 | N7: #VALUE! | O7: Nr. | P7: 6055065 | Q7: #VALUE! | R7: Nr. | S7: 302323 | T7: #VALUE! | U7: Nr. | V7: 407023
C8: Gewicht | D8: 0.2242 | F8: Gewicht | G8: 0.3504 | I8: Gewicht | J8: 0.589 | L8: Gewicht | M8: 0.7661 | O8: Gewicht | P8: 0.306 | R8: Gewicht | S8: 0.334 | U8: Gewicht | V8: 0.3406
C9: Anzahl | D9: 0 | F9: Anzahl | G9: 0 | I9: Anzahl | J9: 0 | L9: Anzahl | M9: 0 | O9: Anzahl | P9: 0 | R9: Anzahl | S9: 0 | U9: Anzahl | V9: 0
B11: Trans-Clear Slope 30 1 x 1 x 2/3 | E11: Black Plate, Round 1 x 1 | H11: Blue Slope 30 1 x 1 x 2/3 | K11: Blue Tile, Round 1 x 1 Quarter | N11: Black Tile 1 x 1 with Groove | Q11: Part 36841 Bracket 1 x 1 - 1 x 1 | T11: Blue Plate 2 x 2 Corner
B12: #VALUE! | C12: Nr. | D12: 6245250 | E12: #VALUE! | F12: Nr. | G12: 614126 | H12: #VALUE! | I12: Nr. | J12: 4296154 | K12: #VALUE! | L12: Nr. | M12: 6302961 | N12: #VALUE! | O12: Nr. | P12: 307026 | Q12: #VALUE! | R12: Nr. | S12: 6299338 | T12: #VALUE! | U12: Nr. | V12: 242023
C13: Gewicht | D13: 0.2116 | F13: Gewicht | G13: 0.1083 | I13: Gewicht | J13: 0.1835 | L13: Gewicht | M13: 0.1066 | O13: Gewicht | P13: 0.1436 | R13: Gewicht | S13: 0.2834 | U13: Gewicht | V13: 0.4974
C14: Anzahl | D14: 2 | F14: Anzahl | G14: 0 | I14: Anzahl | J14: 0 | L14: Anzahl | M14: 0 | O14: Anzahl | P14: 0 | R14: Anzahl | S14: 0 | U14: Anzahl | V14: 0
B16: White Plate 1 x 2 | E16: White Plate 2 x 3 | H16: Yellow Plate, Round 1 x 1 | K16: Light Bluish Gray Plate, Modified with Wheel Holder | N16: Black Bracket 1 x 2 - 1 x 2 | Q16: Black Plate 3 x 3 | T16: Blue Slope 30 1 x 2 x 2/3
B17: #VALUE! | C17: Nr. | D17: 302301 | E17: #VALUE! | F17: Nr. | G17: 302101 | H17: #VALUE! | I17: Nr. | J17: 614124 | K17: #VALUE! | L17: Nr. | M17: 6125569 | N17: #VALUE! | O17: Nr. | P17: 6016172 | Q17: #VALUE! | R17: Nr. | S17: 6174917 | T17: #VALUE! | U17: Nr. | V17: 4651236
C18: Gewicht | D18: 0.3367 | F18: Gewicht | G18: 0.8767 | I18: Gewicht | J18: 0.1088 | L18: Gewicht | M18: 0.4478 | O18: Gewicht | P18: 0.5403 | R18: Gewicht | S18: 1.2561 | U18: Gewicht | V18: 0.2736
C19: Anzahl | D19: 0 | F19: Anzahl | G19: 0 | I19: Anzahl | J19: 0 | L19: Anzahl | M19: 0 | O19: Anzahl | P19: 0 | R19: Anzahl | S19: 0 | U19: Anzahl | V19: 0
B21: Red Bracket 1 x 2 - 1 x 4 with Two Rounded Corners at the Bottom | E21: Trans-Red Tile, Modified 1 x 2 Grille with Bottom Groove / Lip | H21: Red Tile, Round 1 x 1 Quarter | K21: Red Tile, Modified 2 x 2 with Studs on Edge | N21: Red Slope, Curved 2 x 1 x 2/3 | Q21: Red Slope 45 2 x 1 with 2/3 Cutout | T21: Red Plate 1 x 4
B22: #VALUE! | C22: Nr. | D22: 6168619 | E22: #VALUE! | F22: Nr. | G22: 6250158 | H22: #VALUE! | I22: Nr. | J22: 6170390 | K22: #VALUE! | L22: Nr. | M22: 6219819 | N22: #VALUE! | O22: Nr. | P22: 6029946 | Q22: #VALUE! | R22: Nr. | S22: 6053011 | T22: #VALUE! | U22: Nr. | V22: 371021
C23: Gewicht | D23: 0.7817 | F23: Gewicht | G23: 0.2397 | I23: Gewicht | J23: 0.1071 | L23: Gewicht | M23: 0.5492 | O23: Gewicht | P23: 0.3011 | R23: Gewicht | S23: 0.4087 | U23: Gewicht | V23: 0.6503
C24: Anzahl | D24: 2 | F24: Anzahl | G24: 2 | I24: Anzahl | J24: 0 | L24: Anzahl | M24: 2 | O24: Anzahl | P24: 2 | R24: Anzahl | S24: 2 | U24: Anzahl | V24: 2
B26: White Tile, Round 1 x 1 Half Circle Extended | E26: Light Bluish Gray Tile 1 x 1 with Groove | H26: Blue Wedge, Plate 2 x 2 Right | K26: Blue Wedge, Plate 2 x 2 Left | N26: Blue Tile 2 x 2 with Groove | Q26: Red Plate 1 x 2 | T26: Blue Wedge 2 x 1 x 2/3 Right
B27: #VALUE! | C27: Nr. | D27: 6131655 | E27: #VALUE! | F27: Nr. | G27: 4211415 | H27: #VALUE! | I27: Nr. | J27: 6189202 | K27: #VALUE! | L27: Nr. | M27: 6189198 | N27: #VALUE! | O27: Nr. | P27: 306823 | Q27: #VALUE! | R27: Nr. | S27: 302321 | T27: #VALUE! | U27: Nr. | V27: 6172411
C28: Gewicht | D28: 0.1257 | F28: Gewicht | G28: 0.1418 | I28: Gewicht | J28: 0.4511 | L28: Gewicht | M28: 0.4535 | O28: Gewicht | P28: 0.4796 | R28: Gewicht | S28: 0.3331 | U28: Gewicht | V28: 0.2242
C29: Anzahl | D29: 0 | F29: Anzahl | G29: 0 | I29: Anzahl | J29: 0 | L29: Anzahl | M29: 0 | O29: Anzahl | P29: 0 | R29: Anzahl | S29: 2 | U29: Anzahl | V29: 0
B31: Blue Tile 1 x 2 with Groove | E31: Blue Plate 1 x 10 | H31: Black Tile, Modified 1 x 2 Grille with Bottom Groove / Lip | K31: Black Tile, 1 x 4 | N31: Red Slope, Curved 4 x 2 | Q31: Red Vehicla, Mudguard 2 x 4 with Arch Studded with Hole | T31: Red Wedge 3 x 4 x 2/3 Curved with Cutout
B32: #VALUE! | C32: Nr. | D32: 306923 | E32: #VALUE! | F32: Nr. | G32: 447723 | H32: #VALUE! | I32: Nr. | J32: 241226 | K32: #VALUE! | L32: Nr. | M32: 243126 | N32: #VALUE! | O32: Nr. | P32: 4613174 | Q32: #VALUE! | R32: Nr. | S32: 4518231 | T32: #VALUE! | U32: Nr. | V32: 6179656
C33: Gewicht | D33: 0.2575 | F33: Gewicht | G33: 1.6056 | I33: Gewicht | J33: 0.2158 | L33: Gewicht | M33: 0.5271 | O33: Gewicht | P33: 1.3333 | R33: Gewicht | S33: 1.3094 | U33: Gewicht | V33: 1.4239
C34: Anzahl | D34: 0 | F34: Anzahl | G34: 0 | I34: Anzahl | J34: 0 | L34: Anzahl | M34: 1 | O34: Anzahl | P34: 1 | R34: Anzahl | S34: 1 | U34: Anzahl | V34: 1
B36: Lagerbock 100-000-001 | E36: Sicherungsring DIN 471 - 1,0 x 1,0 | H36: Sicherungsring DIN 472 - 30 x 1,2 | K36: Rillenkugellager DIN 625 - 6200 - P2 | N36: Gewindestift ISO 4027 - M4 x 6 - A5 - 45H | Q36: Black Plate 2 x 3 | T36: Black Brick, Modified 1 x 1 with Stud on Side
B37: #VALUE! | C37: Nr. | D37: L007001 | E37: #VALUE! | F37: Nr. | G37: L007002 | H37: #VALUE! | I37: Nr. | J37: L007003 | K37: #VALUE! | L37: Nr. | M37: L007004 | N37: #VALUE! | O37: Nr. | P37: L007005 | Q37: #VALUE! | R37: Nr. | S37: 302126 | T37: #VALUE! | U37: Nr. | V37: 4558954
C38: Gewicht | D38: 8.88 | F38: Gewicht | G38: 0.405 | I38: Gewicht | J38: 1.9188 | L38: Gewicht | M38: 30.775 | O38: Gewicht | P38: 0.2825 | R38: Gewicht | S38: 0.8589 | U38: Gewicht | V38: 0.4278
C39: Anzahl | D39: 0 | F39: Anzahl | G39: 0 | I39: Anzahl | J39: 0 | L39: Anzahl | M39: 0 | O39: Anzahl | P39: 0 | R39: Anzahl | S39: 0 | U39: Anzahl | V39: 0
B42: Rechte Seite
B44: Black Bracket 1 x 2 - 1 x 4 with Two Rounded Corners at the Bottom | E44: Black Bracket 1 x 2 - 2 x 2 | H44: Black Plate 1 x 1 | K44: Part 54200 Slope 30 1 x 1 x 2/3 | N44: Dark Orange Plate Round 1 x 1 | Q44: Black Panel 1 x 1 x 1 Corner | T44: Red Plate 1 x 1
B45: #VALUE! | C45: Nr. | D45: 6168620 | E45: #VALUE! | F45: Nr. | G45: 6117973 | H45: #VALUE! | I45: Nr. | J45: 302426 | K45: #VALUE! | L45: Nr. | M45: 4287159 | N45: #VALUE! | O45: Nr. | P45: 6315782 | Q45: #VALUE! | R45: Nr. | S45: 4106347 | T45: #VALUE! | U45: Nr. | V45: 302421
C46: Gewicht | D46: 0.7731 | F46: Gewicht | G46: 0.7924 | I46: Gewicht | J46: 0.1745 | L46: Gewicht | M46: 0.1848 | O46: Gewicht | P46: 0.1043 | R46: Gewicht | S46: 0.2889 | U46: Gewicht | V46: 0.175
C47: Anzahl | D47: 0 | F47: Anzahl | G47: 0 | I47: Anzahl | J47: 2 | L47: Anzahl | M47: 2 | O47: Anzahl | P47: 2 | R47: Anzahl | S47: 2 | U47: Anzahl | V47: 2
B49: Black Wheel 11mm 0. x 6mm with 8 'Y' Spokes | E49: Red Slope 30 1 x 2 x 2/3 | H49: Black Plate 1 x 4 | K49: Black Slope 30 1 x 2 x 2/3 | N49: Black Bracket 1 x 2 - 2 x 4 | Q49: Nougat Plate 2 x 4 | T49: Black Wedge, Plate 2 x 2 Right
B50: #VALUE! | C50: Nr. | D50: 4613162 | E50: #VALUE! | F50: Nr. | G50: 4651524 | H50: #VALUE! | I50: Nr. | J50: 371026 | K50: #VALUE! | L50: Nr. | M50: 4548180 | N50: #VALUE! | O50: Nr. | P50: 6118829 | Q50: #VALUE! | R50: Nr. | S50: 4497049 | T50: #VALUE! | U50: Nr. | V50: 6141556
C51: Gewicht | D51: 0.3292 | F51: Gewicht | G51: 0.3408 | I51: Gewicht | J51: 0.6427 | L51: Gewicht | M51: 0.3507 | O51: Gewicht | P51: 1.2711 | R51: Gewicht | S51: 1.1502 | U51: Gewicht | V51: 0.45
C52: Anzahl | D52: 4 | F52: Anzahl | G52: 5 | I52: Anzahl | J52: 0 | L52: Anzahl | M52: 0 | O52: Anzahl | P52: 3 | R52: Anzahl | S52: 3 | U52: Anzahl | V52: 0
B54: Black Tire 14mm 0. x 6mm Solid Smooth | E54: Black Tile, Modified 2 x 2 with Studs on Edge | H54: Metallic Gold Tile 1 x 2 with Groove | K54: Black Tile 1 x 3 | N54: Black Plate 2 x 6 | Q54: Black Slope, Curved 2 x 1 x 2/3 | T54: White Bracket 1 x 2 - 1 x 4 with Two Rounded Corners at the Bottom
...

Sheet Lamborghini
B2: Kommissioniersystem
B4: Linke Seite
B6: Blue Wedge 2 x 1 x 2/3 Left | E6: Blue Tile, Modified Facet 2 x 2 | H6: Blue Slope, Curved 4 x 1 x 2/3 Double | K6: Blue Slope, Curved 4 x 1 | N6: Blue Slope, Curved 2 x 1 x 2/3 | Q6: Blue Plate 1 x 2 | T6: Blue Brick, Modified 1 x 1 with Headlight
B7: #VALUE! | C7: Nr. | D7: 6172414 | E7: #VALUE! | F7: Nr. | G7: 6333512 | H7: #VALUE! | I7: Nr. | J7: 4649773 | K7: #VALUE! | L7: Nr. | M7: 6045938 | N7: #VALUE! | O7: Nr. | P7: 6055065 | Q7: #VALUE! | R7: Nr. | S7: 302323 | T7: #VALUE! | U7: Nr. | V7: 407023
C8: Gewicht | D8: 0.2242 | F8: Gewicht | G8: 0.3504 | I8: Gewicht | J8: 0.589 | L8: Gewicht | M8: 0.7661 | O8: Gewicht | P8: 0.306 | R8: Gewicht | S8: 0.334 | U8: Gewicht | V8: 0.3406
C9: Anzahl | D9: 0 | F9: Anzahl | G9: 0 | I9: Anzahl | J9: 0 | L9: Anzahl | M9: 0 | O9: Anzahl | P9: 0 | R9: Anzahl | S9: 0 | U9: Anzahl | V9: 0
B11: Trans-Clear Slope 30 1 x 1 x 2/3 | E11: Black Plate, Round 1 x 1 | H11: Blue Slope 30 1 x 1 x 2/3 | K11: Blue Tile, Round 1 x 1 Quarter | N11: Black Tile 1 x 1 with Groove | Q11: Part 36841 Bracket 1 x 1 - 1 x 1 | T11: Blue Plate 2 x 2 Corner
B12: #VALUE! | C12: Nr. | D12: 6245250 | E12: #VALUE! | F12: Nr. | G12: 614126 | H12: #VALUE! | I12: Nr. | J12: 4296154 | K12: #VALUE! | L12: Nr. | M12: 6302961 | N12: #VALUE! | O12: Nr. | P12: 307026 | Q12: #VALUE! | R12: Nr. | S12: 6299338 | T12: #VALUE! | U12: Nr. | V12: 242023
C13: Gewicht | D13: 0.2116 | F13: Gewicht | G13: 0.1083 | I13: Gewicht | J13: 0.1835 | L13: Gewicht | M13: 0.1066 | O13: Gewicht | P13: 0.1436 | R13: Gewicht | S13: 0.2834 | U13: Gewicht | V13: 0.4974
C14: Anzahl | D14: 0 | F14: Anzahl | G14: 0 | I14: Anzahl | J14: 0 | L14: Anzahl | M14: 0 | O14: Anzahl | P14: 5 | R14: Anzahl | S14: 0 | U14: Anzahl | V14: 0
B16: White Plate 1 x 2 | E16: White Plate 2 x 3 | H16: Yellow Plate, Round 1 x 1 | K16: Light Bluish Gray Plate, Modified with Wheel Holder | N16: Black Bracket 1 x 2 - 1 x 2 | Q16: Black Plate 3 x 3 | T16: Blue Slope 30 1 x 2 x 2/3
B17: #VALUE! | C17: Nr. | D17: 302301 | E17: #VALUE! | F17: Nr. | G17: 302101 | H17: #VALUE! | I17: Nr. | J17: 614124 | K17: #VALUE! | L17: Nr. | M17: 6125569 | N17: #VALUE! | O17: Nr. | P17: 6016172 | Q17: #VALUE! | R17: Nr. | S17: 6174917 | T17: #VALUE! | U17: Nr. | V17: 4651236
C18: Gewicht | D18: 0.3367 | F18: Gewicht | G18: 0.8767 | I18: Gewicht | J18: 0.1088 | L18: Gewicht | M18: 0.4478 | O18: Gewicht | P18: 0.5403 | R18: Gewicht | S18: 1.2561 | U18: Gewicht | V18: 0.2736
C19: Anzahl | D19: 1 | F19: Anzahl | G19: 0 | I19: Anzahl | J19: 0 | L19: Anzahl | M19: 0 | O19: Anzahl | P19: 0 | R19: Anzahl | S19: 0 | U19: Anzahl | V19: 0
B21: Red Bracket 1 x 2 - 1 x 4 with Two Rounded Corners at the Bottom | E21: Trans-Red Tile, Modified 1 x 2 Grille with Bottom Groove / Lip | H21: Red Tile, Round 1 x 1 Quarter | K21: Red Tile, Modified 2 x 2 with Studs on Edge | N21: Red Slope, Curved 2 x 1 x 2/3 | Q21: Red Slope 45 2 x 1 with 2/3 Cutout | T21: Red Plate 1 x 4
B22: #VALUE! | C22: Nr. | D22: 6168619 | E22: #VALUE! | F22: Nr. | G22: 6250158 | H22: #VALUE! | I22: Nr. | J22: 6170390 | K22: #VALUE! | L22: Nr. | M22: 6219819 | N22: #VALUE! | O22: Nr. | P22: 6029946 | Q22: #VALUE! | R22: Nr. | S22: 6053011 | T22: #VALUE! | U22: Nr. | V22: 371021
C23: Gewicht | D23: 0.7817 | F23: Gewicht | G23: 0.2397 | I23: Gewicht | J23: 0.1071 | L23: Gewicht | M23: 0.5492 | O23: Gewicht | P23: 0.3011 | R23: Gewicht | S23: 0.4087 | U23: Gewicht | V23: 0.6503
C24: Anzahl | D24: 0 | F24: Anzahl | G24: 0 | I24: Anzahl | J24: 0 | L24: Anzahl | M24: 0 | O24: Anzahl | P24: 0 | R24: Anzahl | S24: 0 | U24: Anzahl | V24: 0
B26: White Tile, Round 1 x 1 Half Circle Extended | E26: Light Bluish Gray Tile 1 x 1 with Groove | H26: Blue Wedge, Plate 2 x 2 Right | K26: Blue Wedge, Plate 2 x 2 Left | N26: Blue Tile 2 x 2 with Groove | Q26: Red Plate 1 x 2 | T26: Blue Wedge 2 x 1 x 2/3 Right
B27: #VALUE! | C27: Nr. | D27: 6131655 | E27: #VALUE! | F27: Nr. | G27: 4211415 | H27: #VALUE! | I27: Nr. | J27: 6189202 | K27: #VALUE! | L27: Nr. | M27: 6189198 | N27: #VALUE! | O27: Nr. | P27: 306823 | Q27: #VALUE! | R27: Nr. | S27: 302321 | T27: #VALUE! | U27: Nr. | V27: 6172411
C28: Gewicht | D28: 0.1257 | F28: Gewicht | G28: 0.1418 | I28: Gewicht | J28: 0.4511 | L28: Gewicht | M28: 0.4535 | O28: Gewicht | P28: 0.4796 | R28: Gewicht | S28: 0.3331 | U28: Gewicht | V28: 0.2242
C29: Anzahl | D29: 0 | F29: Anzahl | G29: 0 | I29: Anzahl | J29: 0 | L29: Anzahl | M29: 0 | O29: Anzahl | P29: 0 | R29: Anzahl | S29: 0 | U29: Anzahl | V29: 0
B31: Blue Tile 1 x 2 with Groove | E31: Blue Plate 1 x 10 | H31: Black Tile, Modified 1 x 2 Grille with Bottom Groove / Lip | K31: Black Tile, 1 x 4 | N31: Red Slope, Curved 4 x 2 | Q31: Red Vehicla, Mudguard 2 x 4 with Arch Studded with Hole | T31: Red Wedge 3 x 4 x 2/3 Curved with Cutout
B32: #VALUE! | C32: Nr. | D32: 306923 | E32: #VALUE! | F32: Nr. | G32: 447723 | H32: #VALUE! | I32: Nr. | J32: 241226 | K32: #VALUE! | L32: Nr. | M32: 243126 | N32: #VALUE! | O32: Nr. | P32: 4613174 | Q32: #VALUE! | R32: Nr. | S32: 4518231 | T32: #VALUE! | U32: Nr. | V32: 6179656
C33: Gewicht | D33: 0.2575 | F33: Gewicht | G33: 1.6056 | I33: Gewicht | J33: 0.2158 | L33: Gewicht | M33: 0.5271 | O33: Gewicht | P33: 1.3333 | R33: Gewicht | S33: 1.3094 | U33: Gewicht | V33: 1.4239
C34: Anzahl | D34: 0 | F34: Anzahl | G34: 0 | I34: Anzahl | J34: 0 | L34: Anzahl | M34: 3 | O34: Anzahl | P34: 0 | R34: Anzahl | S34: 0 | U34: Anzahl | V34: 0
B36: Lagerbock 100-000-001 | E36: Sicherungsring DIN 471 - 1,0 x 1,0 | H36: Sicherungsring DIN 472 - 30 x 1,2 | K36: Rillenkugellager DIN 625 - 6200 - P2 | N36: Gewindestift ISO 4027 - M4 x 6 - A5 - 45H | Q36: Black Plate 2 x 3 | T36: Black Brick, Modified 1 x 1 with Stud on Side
B37: #VALUE! | C37: Nr. | D37: L007001 | E37: #VALUE! | F37: Nr. | G37: L007002 | H37: #VALUE! | I37: Nr. | J37: L007003 | K37: #VALUE! | L37: Nr. | M37: L007004 | N37: #VALUE! | O37: Nr. | P37: L007005 | Q37: #VALUE! | R37: Nr. | S37: 302126 | T37: #VALUE! | U37: Nr. | V37: 4558954
C38: Gewicht | D38: 8.88 | F38: Gewicht | G38: 0.405 | I38: Gewicht | J38: 1.9188 | L38: Gewicht | M38: 30.775 | O38: Gewicht | P38: 0.2825 | R38: Gewicht | S38: 0.8589 | U38: Gewicht | V38: 0.4278
C39: Anzahl | D39: 0 | F39: Anzahl | G39: 0 | I39: Anzahl | J39: 0 | L39: Anzahl | M39: 0 | O39: Anzahl | P39: 0 | R39: Anzahl | S39: 0 | U39: Anzahl | V39: 0
B42: Rechte Seite
B44: Black Bracket 1 x 2 - 1 x 4 with Two Rounded Corners at the Bottom | E44: Black Bracket 1 x 2 - 2 x 2 | H44: Black Plate 1 x 1 | K44: Part 54200 Slope 30 1 x 1 x 2/3 | N44: Dark Orange Plate Round 1 x 1 | Q44: Black Panel 1 x 1 x 1 Corner | T44: Red Plate 1 x 1
B45: #VALUE! | C45: Nr. | D45: 6168620 | E45: #VALUE! | F45: Nr. | G45: 6117973 | H45: #VALUE! | I45: Nr. | J45: 302426 | K45: #VALUE! | L45: Nr. | M45: 4287159 | N45: #VALUE! | O45: Nr. | P45: 6315782 | Q45: #VALUE! | R45: Nr. | S45: 4106347 | T45: #VALUE! | U45: Nr. | V45: 302421
C46: Gewicht | D46: 0.7731 | F46: Gewicht | G46: 0.7924 | I46: Gewicht | J46: 0.1745 | L46: Gewicht | M46: 0.1848 | O46: Gewicht | P46: 0.1043 | R46: Gewicht | S46: 0.2889 | U46: Gewicht | V46: 0.175
C47: Anzahl | D47: 2 | F47: Anzahl | G47: 2 | I47: Anzahl | J47: 2 | L47: Anzahl | M47: 0 | O47: Anzahl | P47: 0 | R47: Anzahl | S47: 0 | U47: Anzahl | V47: 0
B49: Black Wheel 11mm 0. x 6mm with 8 'Y' Spokes | E49: Red Slope 30 1 x 2 x 2/3 | H49: Black Plate 1 x 4 | K49: Black Slope 30 1 x 2 x 2/3 | N49: Black Bracket 1 x 2 - 2 x 4 | Q49: Nougat Plate 2 x 4 | T49: Black Wedge, Plate 2 x 2 Right
B50: #VALUE! | C50: Nr. | D50: 4613162 | E50: #VALUE! | F50: Nr. | G50: 4651524 | H50: #VALUE! | I50: Nr. | J50: 371026 | K50: #VALUE! | L50: Nr. | M50: 4548180 | N50: #VALUE! | O50: Nr. | P50: 6118829 | Q50: #VALUE! | R50: Nr. | S50: 4497049 | T50: #VALUE! | U50: Nr. | V50: 6141556
C51: Gewicht | D51: 0.3292 | F51: Gewicht | G51: 0.3408 | I51: Gewicht | J51: 0.6427 | L51: Gewicht | M51: 0.3507 | O51: Gewicht | P51: 1.2711 | R51: Gewicht | S51: 1.1502 | U51: Gewicht | V51: 0.45
C52: Anzahl | D52: 4 | F52: Anzahl | G52: 0 | I52: Anzahl | J52: 4 | L52: Anzahl | M52: 3 | O52: Anzahl | P52: 0 | R52: Anzahl | S52: 0 | U52: Anzahl | V52: 2
B54: Black Tire 14mm 0. x 6mm Solid Smooth | E54: Black Tile, Modified 2 x 2 with Studs on Edge | H54: Metallic Gold Tile 1 x 2 with Groove | K54: Black Tile 1 x 3 | N54: Black Plate 2 x 6 | Q54: Black Slope, Curved 2 x 1 x 2/3 | T54: White Bracket 1 x 2 - 1 x 4 with Two Rounded Corners at the Bottom
...

Sheet McLaren
B2: Kommissioniersystem
B4: Linke Seite
B6: Blue Wedge 2 x 1 x 2/3 Left | E6: Blue Tile, Modified Facet 2 x 2 | H6: Blue Slope, Curved 4 x 1 x 2/3 Double | K6: Blue Slope, Curved 4 x 1 | N6: Blue Slope, Curved 2 x 1 x 2/3 | Q6: Blue Plate 1 x 2 | T6: Blue Brick, Modified 1 x 1 with Headlight
B7: #VALUE! | C7: Nr. | D7: 6172414 | E7: #VALUE! | F7: Nr. | G7: 6333512 | H7: #VALUE! | I7: Nr. | J7: 4649773 | K7: #VALUE! | L7: Nr. | M7: 6045938 | N7: #VALUE! | O7: Nr. | P7: 6055065 | Q7: #VALUE! | R7: Nr. | S7: 302323 | T7: #VALUE! | U7: Nr. | V7: 407023
C8: Gewicht | D8: 0.2242 | F8: Gewicht | G8: 0.3504 | I8: Gewicht | J8: 0.589 | L8: Gewicht | M8: 0.7661 | O8: Gewicht | P8: 0.306 | R8: Gewicht | S8: 0.334 | U8: Gewicht | V8: 0.3406
C9: Anzahl | D9: 2 | F9: Anzahl | G9: 2 | I9: Anzahl | J9: 2 | L9: Anzahl | M9: 2 | O9: Anzahl | P9: 2 | R9: Anzahl | S9: 2 | U9: Anzahl | V9: 2
B11: Trans-Clear Slope 30 1 x 1 x 2/3 | E11: Black Plate, Round 1 x 1 | H11: Blue Slope 30 1 x 1 x 2/3 | K11: Blue Tile, Round 1 x 1 Quarter | N11: Black Tile 1 x 1 with Groove | Q11: Part 36841 Bracket 1 x 1 - 1 x 1 | T11: Blue Plate 2 x 2 Corner
B12: #VALUE! | C12: Nr. | D12: 6245250 | E12: #VALUE! | F12: Nr. | G12: 614126 | H12: #VALUE! | I12: Nr. | J12: 4296154 | K12: #VALUE! | L12: Nr. | M12: 6302961 | N12: #VALUE! | O12: Nr. | P12: 307026 | Q12: #VALUE! | R12: Nr. | S12: 6299338 | T12: #VALUE! | U12: Nr. | V12: 242023
C13: Gewicht | D13: 0.2116 | F13: Gewicht | G13: 0.1083 | I13: Gewicht | J13: 0.1835 | L13: Gewicht | M13: 0.1066 | O13: Gewicht | P13: 0.1436 | R13: Gewicht | S13: 0.2834 | U13: Gewicht | V13: 0.4974
C14: Anzahl | D14: 0 | F14: Anzahl | G14: 3 | I14: Anzahl | J14: 3 | L14: Anzahl | M14: 4 | O14: Anzahl | P14: 1 | R14: Anzahl | S14: 6 | U14: Anzahl | V14: 8
B16: White Plate 1 x 2 | E16: White Plate 2 x 3 | H16: Yellow Plate, Round 1 x 1 | K16: Light Bluish Gray Plate, Modified with Wheel Holder | N16: Black Bracket 1 x 2 - 1 x 2 | Q16: Black Plate 3 x 3 | T16: Blue Slope 30 1 x 2 x 2/3
B17: #VALUE! | C17: Nr. | D17: 302301 | E17: #VALUE! | F17: Nr. | G17: 302101 | H17: #VALUE! | I17: Nr. | J17: 614124 | K17: #VALUE! | L17: Nr. | M17: 6125569 | N17: #VALUE! | O17: Nr. | P17: 6016172 | Q17: #VALUE! | R17: Nr. | S17: 6174917 | T17: #VALUE! | U17: Nr. | V17: 4651236
C18: Gewicht | D18: 0.3367 | F18: Gewicht | G18: 0.8767 | I18: Gewicht | J18: 0.1088 | L18: Gewicht | M18: 0.4478 | O18: Gewicht | P18: 0.5403 | R18: Gewicht | S18: 1.2561 | U18: Gewicht | V18: 0.2736
C19: Anzahl | D19: 0 | F19: Anzahl | G19: 1 | I19: Anzahl | J19: 3 | L19: Anzahl | M19: 4 | O19: Anzahl | P19: 4 | R19: Anzahl | S19: 4 | U19: Anzahl | V19: 4
B21: Red Bracket 1 x 2 - 1 x 4 with Two Rounded Corners at the Bottom | E21: Trans-Red Tile, Modified 1 x 2 Grille with Bottom Groove / Lip | H21: Red Tile, Round 1 x 1 Quarter | K21: Red Tile, Modified 2 x 2 with Studs on Edge | N21: Red Slope, Curved 2 x 1 x 2/3 | Q21: Red Slope 45 2 x 1 with 2/3 Cutout | T21: Red Plate 1 x 4
B22: #VALUE! | C22: Nr. | D22: 6168619 | E22: #VALUE! | F22: Nr. | G22: 6250158 | H22: #VALUE! | I22: Nr. | J22: 6170390 | K22: #VALUE! | L22: Nr. | M22: 6219819 | N22: #VALUE! | O22: Nr. | P22: 6029946 | Q22: #VALUE! | R22: Nr. | S22: 6053011 | T22: #VALUE! | U22: Nr. | V22: 371021
C23: Gewicht | D23: 0.7817 | F23: Gewicht | G23: 0.2397 | I23: Gewicht | J23: 0.1071 | L23: Gewicht | M23: 0.5492 | O23: Gewicht | P23: 0.3011 | R23: Gewicht | S23: 0.4087 | U23: Gewicht | V23: 0.6503
C24: Anzahl | D24: 0 | F24: Anzahl | G24: 0 | I24: Anzahl | J24: 2 | L24: Anzahl | M24: 0 | O24: Anzahl | P24: 0 | R24: Anzahl | S24: 0 | U24: Anzahl | V24: 0
B26: White Tile, Round 1 x 1 Half Circle Extended | E26: Light Bluish Gray Tile 1 x 1 with Groove | H26: Blue Wedge, Plate 2 x 2 Right | K26: Blue Wedge, Plate 2 x 2 Left | N26: Blue Tile 2 x 2 with Groove | Q26: Red Plate 1 x 2 | T26: Blue Wedge 2 x 1 x 2/3 Right
B27: #VALUE! | C27: Nr. | D27: 6131655 | E27: #VALUE! | F27: Nr. | G27: 4211415 | H27: #VALUE! | I27: Nr. | J27: 6189202 | K27: #VALUE! | L27: Nr. | M27: 6189198 | N27: #VALUE! | O27: Nr. | P27: 306823 | Q27: #VALUE! | R27: Nr. | S27: 302321 | T27: #VALUE! | U27: Nr. | V27: 6172411
C28: Gewicht | D28: 0.1257 | F28: Gewicht | G28: 0.1418 | I28: Gewicht | J28: 0.4511 | L28: Gewicht | M28: 0.4535 | O28: Gewicht | P28: 0.4796 | R28: Gewicht | S28: 0.3331 | U28: Gewicht | V28: 0.2242
C29: Anzahl | D29: 2 | F29: Anzahl | G29: 1 | I29: Anzahl | J29: 1 | L29: Anzahl | M29: 1 | O29: Anzahl | P29: 1 | R29: Anzahl | S29: 0 | U29: Anzahl | V29: 2
B31: Blue Tile 1 x 2 with Groove | E31: Blue Plate 1 x 10 | H31: Black Tile, Modified 1 x 2 Grille with Bottom Groove / Lip | K31: Black Tile, 1 x 4 | N31: Red Slope, Curved 4 x 2 | Q31: Red Vehicla, Mudguard 2 x 4 with Arch Studded with Hole | T31: Red Wedge 3 x 4 x 2/3 Curved with Cutout
B32: #VALUE! | C32: Nr. | D32: 306923 | E32: #VALUE! | F32: Nr. | G32: 447723 | H32: #VALUE! | I32: Nr. | J32: 241226 | K32: #VALUE! | L32: Nr. | M32: 243126 | N32: #VALUE! | O32: Nr. | P32: 4613174 | Q32: #VALUE! | R32: Nr. | S32: 4518231 | T32: #VALUE! | U32: Nr. | V32: 6179656
C33: Gewicht | D33: 0.2575 | F33: Gewicht | G33: 1.6056 | I33: Gewicht | J33: 0.2158 | L33: Gewicht | M33: 0.5271 | O33: Gewicht | P33: 1.3333 | R33: Gewicht | S33: 1.3094 | U33: Gewicht | V33: 1.4239
C34: Anzahl | D34: 1 | F34: Anzahl | G34: 1 | I34: Anzahl | J34: 1 | L34: Anzahl | M34: 0 | O34: Anzahl | P34: 0 | R34: Anzahl | S34: 0 | U34: Anzahl | V34: 0
B36: Lagerbock 100-000-001 | E36: Sicherungsring DIN 471 - 1,0 x 1,0 | H36: Sicherungsring DIN 472 - 30 x 1,2 | K36: Rillenkugellager DIN 625 - 6200 - P2 | N36: Gewindestift ISO 4027 - M4 x 6 - A5 - 45H | Q36: Black Plate 2 x 3 | T36: Black Brick, Modified 1 x 1 with Stud on Side
B37: #VALUE! | C37: Nr. | D37: L007001 | E37: #VALUE! | F37: Nr. | G37: L007002 | H37: #VALUE! | I37: Nr. | J37: L007003 | K37: #VALUE! | L37: Nr. | M37: L007004 | N37: #VALUE! | O37: Nr. | P37: L007005 | Q37: #VALUE! | R37: Nr. | S37: 302126 | T37: #VALUE! | U37: Nr. | V37: 4558954
C38: Gewicht | D38: 8.88 | F38: Gewicht | G38: 0.405 | I38: Gewicht | J38: 1.9188 | L38: Gewicht | M38: 30.775 | O38: Gewicht | P38: 0.2825 | R38: Gewicht | S38: 0.8589 | U38: Gewicht | V38: 0.4278
C39: Anzahl | D39: 0 | F39: Anzahl | G39: 0 | I39: Anzahl | J39: 0 | L39: Anzahl | M39: 0 | O39: Anzahl | P39: 0 | R39: Anzahl | S39: 1 | U39: Anzahl | V39: 1
B42: Rechte Seite
B44: Black Bracket 1 x 2 - 1 x 4 with Two Rounded Corners at the Bottom | E44: Black Bracket 1 x 2 - 2 x 2 | H44: Black Plate 1 x 1 | K44: Part 54200 Slope 30 1 x 1 x 2/3 | N44: Dark Orange Plate Round 1 x 1 | Q44: Black Panel 1 x 1 x 1 Corner | T44: Red Plate 1 x 1
B45: #VALUE! | C45: Nr. | D45: 6168620 | E45: #VALUE! | F45: Nr. | G45: 6117973 | H45: #VALUE! | I45: Nr. | J45: 302426 | K45: #VALUE! | L45: Nr. | M45: 4287159 | N45: #VALUE! | O45: Nr. | P45: 6315782 | Q45: #VALUE! | R45: Nr. | S45: 4106347 | T45: #VALUE! | U45: Nr. | V45: 302421
C46: Gewicht | D46: 0.7731 | F46: Gewicht | G46: 0.7924 | I46: Gewicht | J46: 0.1745 | L46: Gewicht | M46: 0.1848 | O46: Gewicht | P46: 0.1043 | R46: Gewicht | S46: 0.2889 | U46: Gewicht | V46: 0.175
C47: Anzahl | D47: 0 | F47: Anzahl | G47: 0 | I47: Anzahl | J47: 0 | L47: Anzahl | M47: 0 | O47: Anzahl | P47: 0 | R47: Anzahl | S47: 0 | U47: Anzahl | V47: 0
B49: Black Wheel 11mm 0. x 6mm with 8 'Y' Spokes | E49: Red Slope 30 1 x 2 x 2/3 | H49: Black Plate 1 x 4 | K49: Black Slope 30 1 x 2 x 2/3 | N49: Black Bracket 1 x 2 - 2 x 4 | Q49: Nougat Plate 2 x 4 | T49: Black Wedge, Plate 2 x 2 Right
B50: #VALUE! | C50: Nr. | D50: 4613162 | E50: #VALUE! | F50: Nr. | G50: 4651524 | H50: #VALUE! | I50: Nr. | J50: 371026 | K50: #VALUE! | L50: Nr. | M50: 4548180 | N50: #VALUE! | O50: Nr. | P50: 6118829 | Q50: #VALUE! | R50: Nr. | S50: 4497049 | T50: #VALUE! | U50: Nr. | V50: 6141556
C51: Gewicht | D51: 0.3292 | F51: Gewicht | G51: 0.3408 | I51: Gewicht | J51: 0.6427 | L51: Gewicht | M51: 0.3507 | O51: Gewicht | P51: 1.2711 | R51: Gewicht | S51: 1.1502 | U51: Gewicht | V51: 0.45
C52: Anzahl | D52: 4 | F52: Anzahl | G52: 0 | I52: Anzahl | J52: 0 | L52: Anzahl | M52: 0 | O52: Anzahl | P52: 0 | R52: Anzahl | S52: 0 | U52: Anzahl | V52: 0
B54: Black Tire 14mm 0. x 6mm Solid Smooth | E54: Black Tile, Modified 2 x 2 with Studs on Edge | H54: Metallic Gold Tile 1 x 2 with Groove | K54: Black Tile 1 x 3 | N54: Black Plate 2 x 6 | Q54: Black Slope, Curved 2 x 1 x 2/3 | T54: White Bracket 1 x 2 - 1 x 4 with Two Rounded Corners at the Bottom
...

Sheet Gesamtuebersicht_Summe
B2: Kommissioniersystem
B4: Linke Seite
B6: Blue Wedge 2 x 1 x 2/3 Left | E6: Blue Tile, Modified Facet 2 x 2 | H6: Blue Slope, Curved 4 x 1 x 2/3 Double | K6: Blue Slope, Curved 4 x 1 | N6: Blue Slope, Curved 2 x 1 x 2/3 | Q6: Blue Plate 1 x 2 | T6: Blue Brick, Modified 1 x 1 with Headlight
B7: #VALUE! | C7: Nr. | D7: 6172414 | E7: #VALUE! | F7: Nr. | G7: 6333512 | H7: #VALUE! | I7: Nr. | J7: 4649773 | K7: #VALUE! | L7: Nr. | M7: 6045938 | N7: #VALUE! | O7: Nr. | P7: 6055065 | Q7: #VALUE! | R7: Nr. | S7: 302323 | T7: #VALUE! | U7: Nr. | V7: 407023
C8: Gewicht | D8: 0.2242 | F8: Gewicht | G8: 0.3504 | I8: Gewicht | J8: 0.589 | L8: Gewicht | M8: 0.7661 | O8: Gewicht | P8: 0.306 | R8: Gewicht | S8: 0.334 | U8: Gewicht | V8: 0.3406
C9: Anzahl | D9: =Muscle_Car!D9+Lamborghini!D9+McLaren!D9 -> 2 | F9: Anzahl | G9: =Muscle_Car!G9+Lamborghini!G9+McLaren!G9 -> 2 | I9: Anzahl | J9: =Muscle_Car!J9+Lamborghini!J9+McLaren!J9 -> 2 | L9: Anzahl | M9: =Muscle_Car!M9+Lamborghini!M9+McLaren!M9 -> 2 | O9: Anzahl | P9: =Muscle_Car!P9+Lamborghini!P9+McLaren!P9 -> 2 | R9: Anzahl | S9: =Muscle_Car!S9+Lamborghini!S9+McLaren!S9 -> 2 | U9: Anzahl | V9: =Muscle_Car!V9+Lamborghini!V9+McLaren!V9 -> 2
B11: Trans-Clear Slope 30 1 x 1 x 2/3 | E11: Black Plate, Round 1 x 1 | H11: Blue Slope 30 1 x 1 x 2/3 | K11: Blue Tile, Round 1 x 1 Quarter | N11: Black Tile 1 x 1 with Groove | Q11: Part 36841 Bracket 1 x 1 - 1 x 1 | T11: Blue Plate 2 x 2 Corner
B12: #VALUE! | C12: Nr. | D12: 6245250 | E12: #VALUE! | F12: Nr. | G12: 614126 | H12: #VALUE! | I12: Nr. | J12: 4296154 | K12: #VALUE! | L12: Nr. | M12: 6302961 | N12: #VALUE! | O12: Nr. | P12: 307026 | Q12: #VALUE! | R12: Nr. | S12: 6299338 | T12: #VALUE! | U12: Nr. | V12: 242023
C13: Gewicht | D13: 0.2116 | F13: Gewicht | G13: 0.1083 | I13: Gewicht | J13: 0.1835 | L13: Gewicht | M13: 0.1066 | O13: Gewicht | P13: 0.1436 | R13: Gewicht | S13: 0.2834 | U13: Gewicht | V13: 0.4974
C14: Anzahl | D14: =Muscle_Car!D14+Lamborghini!D14+McLaren!D14 -> 2 | F14: Anzahl | G14: =Muscle_Car!G14+Lamborghini!G14+McLaren!G14 -> 3 | I14: Anzahl | J14: =Muscle_Car!J14+Lamborghini!J14+McLaren!J14 -> 3 | L14: Anzahl | M14: =Muscle_Car!M14+Lamborghini!M14+McLaren!M14 -> 4 | O14: Anzahl | P14: =Muscle_Car!P14+Lamborghini!P14+McLaren!P14 -> 6 | R14: Anzahl | S14: =Muscle_Car!S14+Lamborghini!S14+McLaren!S14 -> 6 | U14: Anzahl | V14: =Muscle_Car!V14+Lamborghini!V14+McLaren!V14 -> 8
B16: White Plate 1 x 2 | E16: White Plate 2 x 3 | H16: Yellow Plate, Round 1 x 1 | K16: Light Bluish Gray Plate, Modified with Wheel Holder | N16: Black Bracket 1 x 2 - 1 x 2 | Q16: Black Plate 3 x 3 | T16: Blue Slope 30 1 x 2 x 2/3
B17: #VALUE! | C17: Nr. | D17: 302301 | E17: #VALUE! | F17: Nr. | G17: 302101 | H17: #VALUE! | I17: Nr. | J17: 614124 | K17: #VALUE! | L17: Nr. | M17: 6125569 | N17: #VALUE! | O17: Nr. | P17: 6016172 | Q17: #VALUE! | R17: Nr. | S17: 6174917 | T17: #VALUE! | U17: Nr. | V17: 4651236
C18: Gewicht | D18: 0.3367 | F18: Gewicht | G18: 0.8767 | I18: Gewicht | J18: 0.1088 | L18: Gewicht | M18: 0.4478 | O18: Gewicht | P18: 0.5403 | R18: Gewicht | S18: 1.2561 | U18: Gewicht | V18: 0.2736
C19: Anzahl | D19: =Muscle_Car!D19+Lamborghini!D19+McLaren!D19 -> 1 | F19: Anzahl | G19: =Muscle_Car!G19+Lamborghini!G19+McLaren!G19 -> 1 | I19: Anzahl | J19: =Muscle_Car!J19+Lamborghini!J19+McLaren!J19 -> 3 | L19: Anzahl | M19: =Muscle_Car!M19+Lamborghini!M19+McLaren!M19 -> 4 | O19: Anzahl | P19: =Muscle_Car!P19+Lamborghini!P19+McLaren!P19 -> 4 | R19: Anzahl | S19: =Muscle_Car!S19+Lamborghini!S19+McLaren!S19 -> 4 | U19: Anzahl | V19: =Muscle_Car!V19+Lamborghini!V19+McLaren!V19 -> 4
B21: Red Bracket 1 x 2 - 1 x 4 with Two Rounded Corners at the Bottom | E21: Trans-Red Tile, Modified 1 x 2 Grille with Bottom Groove / Lip | H21: Red Tile, Round 1 x 1 Quarter | K21: Red Tile, Modified 2 x 2 with Studs on Edge | N21: Red Slope, Curved 2 x 1 x 2/3 | Q21: Red Slope 45 2 x 1 with 2/3 Cutout | T21: Red Plate 1 x 4
B22: #VALUE! | C22: Nr. | D22: 6168619 | E22: #VALUE! | F22: Nr. | G22: 6250158 | H22: #VALUE! | I22: Nr. | J22: 6170390 | K22: #VALUE! | L22: Nr. | M22: 6219819 | N22: #VALUE! | O22: Nr. | P22: 6029946 | Q22: #VALUE! | R22: Nr. | S22: 6053011 | T22: #VALUE! | U22: Nr. | V22: 371021
C23: Gewicht | D23: 0.7817 | F23: Gewicht | G23: 0.2397 | I23: Gewicht | J23: 0.1071 | L23: Gewicht | M23: 0.5492 | O23: Gewicht | P23: 0.3011 | R23: Gewicht | S23: 0.4087 | U23: Gewicht | V23: 0.6503
C24: Anzahl | D24: =Muscle_Car!D24+Lamborghini!D24+McLaren!D24 -> 2 | F24: Anzahl | G24: =Muscle_Car!G24+Lamborghini!G24+McLaren!G24 -> 2 | I24: Anzahl | J24: =Muscle_Car!J24+Lamborghini!J24+McLaren!J24 -> 2 | L24: Anzahl | M24: =Muscle_Car!M24+Lamborghini!M24+McLaren!M24 -> 2 | O24: Anzahl | P24: =Muscle_Car!P24+Lamborghini!P24+McLaren!P24 -> 2 | R24: Anzahl | S24: =Muscle_Car!S24+Lamborghini!S24+McLaren!S24 -> 2 | U24: Anzahl | V24: =Muscle_Car!V24+Lamborghini!V24+McLaren!V24 -> 2
B26: White Tile, Round 1 x 1 Half Circle Extended | E26: Light Bluish Gray Tile 1 x 1 with Groove | H26: Blue Wedge, Plate 2 x 2 Right | K26: Blue Wedge, Plate 2 x 2 Left | N26: Blue Tile 2 x 2 with Groove | Q26: Red Plate 1 x 2 | T26: Blue Wedge 2 x 1 x 2/3 Right
B27: #VALUE! | C27: Nr. | D27: 6131655 | E27: #VALUE! | F27: Nr. | G27: 4211415 | H27: #VALUE! | I27: Nr. | J27: 6189202 | K27: #VALUE! | L27: Nr. | M27: 6189198 | N27: #VALUE! | O27: Nr. | P27: 306823 | Q27: #VALUE! | R27: Nr. | S27: 302321 | T27: #VALUE! | U27: Nr. | V27: 6172411
C28: Gewicht | D28: 0.1257 | F28: Gewicht | G28: 0.1418 | I28: Gewicht | J28: 0.4511 | L28: Gewicht | M28: 0.4535 | O28: Gewicht | P28: 0.4796 | R28: Gewicht | S28: 0.3331 | U28: Gewicht | V28: 0.2242
C29: Anzahl | D29: =Muscle_Car!D29+Lamborghini!D29+McLaren!D29 -> 2 | F29: Anzahl | G29: =Muscle_Car!G29+Lamborghini!G29+McLaren!G29 -> 1 | I29: Anzahl | J29: =Muscle_Car!J29+Lamborghini!J29+McLaren!J29 -> 1 | L29: Anzahl | M29: =Muscle_Car!M29+Lamborghini!M29+McLaren!M29 -> 1 | O29: Anzahl | P29: =Muscle_Car!P29+Lamborghini!P29+McLaren!P29 -> 1 | R29: Anzahl | S29: =Muscle_Car!S29+Lamborghini!S29+McLaren!S29 -> 2 | U29: Anzahl | V29: =Muscle_Car!V29+Lamborghini!V29+McLaren!V29 -> 2
B31: Blue Tile 1 x 2 with Groove | E31: Blue Plate 1 x 10 | H31: Black Tile, Modified 1 x 2 Grille with Bottom Groove / Lip | K31: Black Tile, 1 x 4 | N31: Red Slope, Curved 4 x 2 | Q31: Red Vehicla, Mudguard 2 x 4 with Arch Studded with Hole | T31: Red Wedge 3 x 4 x 2/3 Curved with Cutout
B32: #VALUE! | C32: Nr. | D32: 306923 | E32: #VALUE! | F32: Nr. | G32: 447723 | H32: #VALUE! | I32: Nr. | J32: 241226 | K32: #VALUE! | L32: Nr. | M32: 243126 | N32: #VALUE! | O32: Nr. | P32: 4613174 | Q32: #VALUE! | R32: Nr. | S32: 4518231 | T32: #VALUE! | U32: Nr. | V32: 6179656
C33: Gewicht | D33: 0.2575 | F33: Gewicht | G33: 1.6056 | I33: Gewicht | J33: 0.2158 | L33: Gewicht | M33: 0.5271 | O33: Gewicht | P33: 1.3333 | R33: Gewicht | S33: 1.3094 | U33: Gewicht | V33: 1.4239
C34: Anzahl | D34: =Muscle_Car!D34+Lamborghini!D34+McLaren!D34 -> 1 | F34: Anzahl | G34: =Muscle_Car!G34+Lamborghini!G34+McLaren!G34 -> 1 | I34: Anzahl | J34: =Muscle_Car!J34+Lamborghini!J34+McLaren!J34 -> 1 | L34: Anzahl | M34: =Muscle_Car!M34+Lamborghini!M34+McLaren!M34 -> 4 | O34: Anzahl | P34: =Muscle_Car!P34+Lamborghini!P34+McLaren!P34 -> 1 | R34: Anzahl | S34: =Muscle_Car!S34+Lamborghini!S34+McLaren!S34 -> 1 | U34: Anzahl | V34: =Muscle_Car!V34+Lamborghini!V34+McLaren!V34 -> 1
B36: Lagerbock 100-000-001 | E36: Sicherungsring DIN 471 - 1,0 x 1,0 | H36: Sicherungsring DIN 472 - 30 x 1,2 | K36: Rillenkugellager DIN 625 - 6200 - P2 | N36: Gewindestift ISO 4027 - M4 x 6 - A5 - 45H | Q36: Black Plate 2 x 3 | T36: Black Brick, Modified 1 x 1 with Stud on Side
B37: #VALUE! | C37: Nr. | D37: L007001 | E37: #VALUE! | F37: Nr. | G37: L007002 | H37: #VALUE! | I37: Nr. | J37: L007003 | K37: #VALUE! | L37: Nr. | M37: L007004 | N37: #VALUE! | O37: Nr. | P37: L007005 | Q37: #VALUE! | R37: Nr. | S37: 302126 | T37: #VALUE! | U37: Nr. | V37: 4558954
C38: Gewicht | D38: 8.88 | F38: Gewicht | G38: 0.405 | I38: Gewicht | J38: 1.9188 | L38: Gewicht | M38: 30.775 | O38: Gewicht | P38: 0.2825 | R38: Gewicht | S38: 0.8589 | U38: Gewicht | V38: 0.4278
C39: Anzahl | D39: =Muscle_Car!D39+Lamborghini!D39+McLaren!D39 -> 0 | F39: Anzahl | G39: =Muscle_Car!G39+Lamborghini!G39+McLaren!G39 -> 0 | I39: Anzahl | J39: =Muscle_Car!J39+Lamborghini!J39+McLaren!J39 -> 0 | L39: Anzahl | M39: =Muscle_Car!M39+Lamborghini!M39+McLaren!M39 -> 0 | O39: Anzahl | P39: =Muscle_Car!P39+Lamborghini!P39+McLaren!P39 -> 0 | R39: Anzahl | S39: =Muscle_Car!S39+Lamborghini!S39+McLaren!S39 -> 1 | U39: Anzahl | V39: =Muscle_Car!V39+Lamborghini!V39+McLaren!V39 -> 1
B42: Rechte Seite
B44: Black Bracket 1 x 2 - 1 x 4 with Two Rounded Corners at the Bottom | E44: Black Bracket 1 x 2 - 2 x 2 | H44: Black Plate 1 x 1 | K44: Part 54200 Slope 30 1 x 1 x 2/3 | N44: Dark Orange Plate Round 1 x 1 | Q44: Black Panel 1 x 1 x 1 Corner | T44: Red Plate 1 x 1
B45: #VALUE! | C45: Nr. | D45: 6168620 | E45: #VALUE! | F45: Nr. | G45: 6117973 | H45: #VALUE! | I45: Nr. | J45: 302426 | K45: #VALUE! | L45: Nr. | M45: 4287159 | N45: #VALUE! | O45: Nr. | P45: 6315782 | Q45: #VALUE! | R45: Nr. | S45: 4106347 | T45: #VALUE! | U45: Nr. | V45: 302421
C46: Gewicht | D46: 0.7731 | F46: Gewicht | G46: 0.7924 | I46: Gewicht | J46: 0.1745 | L46: Gewicht | M46: 0.1848 | O46: Gewicht | P46: 0.1043 | R46: Gewicht | S46: 0.2889 | U46: Gewicht | V46: 0.175
C47: Anzahl | D47: =Muscle_Car!D47+Lamborghini!D47+McLaren!D47 -> 2 | F47: Anzahl | G47: =Muscle_Car!G47+Lamborghini!G47+McLaren!G47 -> 2 | I47: Anzahl | J47: =Muscle_Car!J47+Lamborghini!J47+McLaren!J47 -> 4 | L47: Anzahl | M47: =Muscle_Car!M47+Lamborghini!M47+McLaren!M47 -> 2 | O47: Anzahl | P47: =Muscle_Car!P47+Lamborghini!P47+McLaren!P47 -> 2 | R47: Anzahl | S47: =Muscle_Car!S47+Lamborghini!S47+McLaren!S47 -> 2 | U47: Anzahl | V47: =Muscle_Car!V47+Lamborghini!V47+McLaren!V47 -> 2
B49: Black Wheel 11mm 0. x 6mm with 8 'Y' Spokes | E49: Red Slope 30 1 x 2 x 2/3 | H49: Black Plate 1 x 4 | K49: Black Slope 30 1 x 2 x 2/3 | N49: Black Bracket 1 x 2 - 2 x 4 | Q49: Nougat Plate 2 x 4 | T49: Black Wedge, Plate 2 x 2 Right
B50: #VALUE! | C50: Nr. | D50: 4613162 | E50: #VALUE! | F50: Nr. | G50: 4651524 | H50: #VALUE! | I50: Nr. | J50: 371026 | K50: #VALUE! | L50: Nr. | M50: 4548180 | N50: #VALUE! | O50: Nr. | P50: 6118829 | Q50: #VALUE! | R50: Nr. | S50: 4497049 | T50: #VALUE! | U50: Nr. | V50: 6141556
C51: Gewicht | D51: 0.3292 | F51: Gewicht | G51: 0.3408 | I51: Gewicht | J51: 0.6427 | L51: Gewicht | M51: 0.3507 | O51: Gewicht | P51: 1.2711 | R51: Gewicht | S51: 1.1502 | U51: Gewicht | V51: 0.45
C52: Anzahl | D52: =Muscle_Car!D52+Lamborghini!D52+McLaren!D52 -> 12 | F52: Anzahl | G52: =Muscle_Car!G52+Lamborghini!G52+McLaren!G52 -> 5 | I52: Anzahl | J52: =Muscle_Car!J52+Lamborghini!J52+McLaren!J52 -> 4 | L52: Anzahl | M52: =Muscle_Car!M52+Lamborghini!M52+McLaren!M52 -> 3 | O52: Anzahl | P52: =Muscle_Car!P52+Lamborghini!P52+McLaren!P52 -> 3 | R52: Anzahl | S52: =Muscle_Car!S52+Lamborghini!S52+McLaren!S52 -> 3 | U52: Anzahl | V52: =Muscle_Car!V52+Lamborghini!V52+McLaren!V52 -> 2
B54: Black Tire 14mm 0. x 6mm Solid Smooth | E54: Black Tile, Modified 2 x 2 with Studs on Edge | H54: Metallic Gold Tile 1 x 2 with Groove | K54: Black Tile 1 x 3 | N54: Black Plate 2 x 6 | Q54: Black Slope, Curved 2 x 1 x 2/3 | T54: White Bracket 1 x 2 - 1 x 4 with Two Rounded Corners at the Bottom
...

Sheet Gesamtuebersicht_Verwendung
B2: Kommissioniersystem
B4: Linke Seite
B6: Blue Wedge 2 x 1 x 2/3 Left | E6: Blue Tile, Modified Facet 2 x 2 | H6: Blue Slope, Curved 4 x 1 x 2/3 Double | K6: Blue Slope, Curved 4 x 1 | N6: Blue Slope, Curved 2 x 1 x 2/3 | Q6: Blue Plate 1 x 2 | T6: Blue Brick, Modified 1 x 1 with Headlight
B7: #VALUE! | C7: Nr. | D7: 6172414 | E7: #VALUE! | F7: Nr. | G7: 6333512 | H7: #VALUE! | I7: Nr. | J7: 4649773 | K7: #VALUE! | L7: Nr. | M7: 6045938 | N7: #VALUE! | O7: Nr. | P7: 6055065 | Q7: #VALUE! | R7: Nr. | S7: 302323 | T7: #VALUE! | U7: Nr. | V7: 407023
C8: Gewicht | D8: 0.2242 | F8: Gewicht | G8: 0.3504 | I8: Gewicht | J8: 0.589 | L8: Gewicht | M8: 0.7661 | O8: Gewicht | P8: 0.306 | R8: Gewicht | S8: 0.334 | U8: Gewicht | V8: 0.3406
C9: Anzahl | D9: =IF(Muscle_Car!D9,IF(Lamborghini!D9,IF(McLaren!D9,3,2),IF(McLaren!D9,2,1)),IF(Lamborghini!D9,IF(McLaren!D9,2,1),IF(McLaren!D9,1,0))) -> 1 | F9: Anzahl | G9: =IF(Muscle_Car!G9,IF(Lamborghini!G9,IF(McLaren!G9,3,2),IF(McLaren!G9,2,1)),IF(Lamborghini!G9,IF(McLaren!G9,2,1),IF(McLaren!G9,1,0))) -> 1 | I9: Anzahl | J9: =IF(Muscle_Car!J9,IF(Lamborghini!J9,IF(McLaren!J9,3,2),IF(McLaren!J9,2,1)),IF(Lamborghini!J9,IF(McLaren!J9,2,1),IF(McLaren!J9,1,0))) -> 1 | L9: Anzahl | M9: =IF(Muscle_Car!M9,IF(Lamborghini!M9,IF(McLaren!M9,3,2),IF(McLaren!M9,2,1)),IF(Lamborghini!M9,IF(McLaren!M9,2,1),IF(McLaren!M9,1,0))) -> 1 | O9: Anzahl | P9: =IF(Muscle_Car!P9,IF(Lamborghini!P9,IF(McLaren!P9,3,2),IF(McLaren!P9,2,1)),IF(Lamborghini!P9,IF(McLaren!P9,2,1),IF(McLaren!P9,1,0))) -> 1 | R9: Anzahl | S9: =IF(Muscle_Car!S9,IF(Lamborghini!S9,IF(McLaren!S9,3,2),IF(McLaren!S9,2,1)),IF(Lamborghini!S9,IF(McLaren!S9,2,1),IF(McLaren!S9,1,0))) -> 1 | U9: Anzahl | V9: =IF(Muscle_Car!V9,IF(Lamborghini!V9,IF(McLaren!V9,3,2),IF(McLaren!V9,2,1)),IF(Lamborghini!V9,IF(McLaren!V9,2,1),IF(McLaren!V9,1,0))) -> 1
B11: Trans-Clear Slope 30 1 x 1 x 2/3 | E11: Black Plate, Round 1 x 1 | H11: Blue Slope 30 1 x 1 x 2/3 | K11: Blue Tile, Round 1 x 1 Quarter | N11: Black Tile 1 x 1 with Groove | Q11: Part 36841 Bracket 1 x 1 - 1 x 1 | T11: Blue Plate 2 x 2 Corner
B12: #VALUE! | C12: Nr. | D12: 6245250 | E12: #VALUE! | F12: Nr. | G12: 614126 | H12: #VALUE! | I12: Nr. | J12: 4296154 | K12: #VALUE! | L12: Nr. | M12: 6302961 | N12: #VALUE! | O12: Nr. | P12: 307026 | Q12: #VALUE! | R12: Nr. | S12: 6299338 | T12: #VALUE! | U12: Nr. | V12: 242023
C13: Gewicht | D13: 0.2116 | F13: Gewicht | G13: 0.1083 | I13: Gewicht | J13: 0.1835 | L13: Gewicht | M13: 0.1066 | O13: Gewicht | P13: 0.1436 | R13: Gewicht | S13: 0.2834 | U13: Gewicht | V13: 0.4974
C14: Anzahl | D14: =IF(Muscle_Car!D14,IF(Lamborghini!D14,IF(McLaren!D14,3,2),IF(McLaren!D14,2,1)),IF(Lamborghini!D14,IF(McLaren!D14,2,1),IF(McLaren!D14,1,0))) -> 1 | F14: Anzahl | G14: =IF(Muscle_Car!G14,IF(Lamborghini!G14,IF(McLaren!G14,3,2),IF(McLaren!G14,2,1)),IF(Lamborghini!G14,IF(McLaren!G14,2,1),IF(McLaren!G14,1,0))) -> 1 | I14: Anzahl | J14: =IF(Muscle_Car!J14,IF(Lamborghini!J14,IF(McLaren!J14,3,2),IF(McLaren!J14,2,1)),IF(Lamborghini!J14,IF(McLaren!J14,2,1),IF(McLaren!J14,1,0))) -> 1 | L14: Anzahl | M14: =IF(Muscle_Car!M14,IF(Lamborghini!M14,IF(McLaren!M14,3,2),IF(McLaren!M14,2,1)),IF(Lamborghini!M14,IF(McLaren!M14,2,1),IF(McLaren!M14,1,0))) -> 1 | O14: Anzahl | P14: =IF(Muscle_Car!P14,IF(Lamborghini!P14,IF(McLaren!P14,3,2),IF(McLaren!P14,2,1)),IF(Lamborghini!P14,IF(McLaren!P14,2,1),IF(McLaren!P14,1,0))) -> 2 | R14: Anzahl | S14: =IF(Muscle_Car!S14,IF(Lamborghini!S14,IF(McLaren!S14,3,2),IF(McLaren!S14,2,1)),IF(Lamborghini!S14,IF(McLaren!S14,2,1),IF(McLaren!S14,1,0))) -> 1 | U14: Anzahl | V14: =IF(Muscle_Car!V14,IF(Lamborghini!V14,IF(McLaren!V14,3,2),IF(McLaren!V14,2,1)),IF(Lamborghini!V14,IF(McLaren!V14,2,1),IF(McLaren!V14,1,0))) -> 1
B16: White Plate 1 x 2 | E16: White Plate 2 x 3 | H16: Yellow Plate, Round 1 x 1 | K16: Light Bluish Gray Plate, Modified with Wheel Holder | N16: Black Bracket 1 x 2 - 1 x 2 | Q16: Black Plate 3 x 3 | T16: Blue Slope 30 1 x 2 x 2/3
B17: #VALUE! | C17: Nr. | D17: 302301 | E17: #VALUE! | F17: Nr. | G17: 302101 | H17: #VALUE! | I17: Nr. | J17: 614124 | K17: #VALUE! | L17: Nr. | M17: 6125569 | N17: #VALUE! | O17: Nr. | P17: 6016172 | Q17: #VALUE! | R17: Nr. | S17: 6174917 | T17: #VALUE! | U17: Nr. | V17: 4651236
C18: Gewicht | D18: 0.3367 | F18: Gewicht | G18: 0.8767 | I18: Gewicht | J18: 0.1088 | L18: Gewicht | M18: 0.4478 | O18: Gewicht | P18: 0.5403 | R18: Gewicht | S18: 1.2561 | U18: Gewicht | V18: 0.2736
C19: Anzahl | D19: =IF(Muscle_Car!D19,IF(Lamborghini!D19,IF(McLaren!D19,3,2),IF(McLaren!D19,2,1)),IF(Lamborghini!D19,IF(McLaren!D19,2,1),IF(McLaren!D19,1,0))) -> 1 | F19: Anzahl | G19: =IF(Muscle_Car!G19,IF(Lamborghini!G19,IF(McLaren!G19,3,2),IF(McLaren!G19,2,1)),IF(Lamborghini!G19,IF(McLaren!G19,2,1),IF(McLaren!G19,1,0))) -> 1 | I19: Anzahl | J19: =IF(Muscle_Car!J19,IF(Lamborghini!J19,IF(McLaren!J19,3,2),IF(McLaren!J19,2,1)),IF(Lamborghini!J19,IF(McLaren!J19,2,1),IF(McLaren!J19,1,0))) -> 1 | L19: Anzahl | M19: =IF(Muscle_Car!M19,IF(Lamborghini!M19,IF(McLaren!M19,3,2),IF(McLaren!M19,2,1)),IF(Lamborghini!M19,IF(McLaren!M19,2,1),IF(McLaren!M19,1,0))) -> 1 | O19: Anzahl | P19: =IF(Muscle_Car!P19,IF(Lamborghini!P19,IF(McLaren!P19,3,2),IF(McLaren!P19,2,1)),IF(Lamborghini!P19,IF(McLaren!P19,2,1),IF(McLaren!P19,1,0))) -> 1 | R19: Anzahl | S19: =IF(Muscle_Car!S19,IF(Lamborghini!S19,IF(McLaren!S19,3,2),IF(McLaren!S19,2,1)),IF(Lamborghini!S19,IF(McLaren!S19,2,1),IF(McLaren!S19,1,0))) -> 1 | U19: Anzahl | V19: =IF(Muscle_Car!V19,IF(Lamborghini!V19,IF(McLaren!V19,3,2),IF(McLaren!V19,2,1)),IF(Lamborghini!V19,IF(McLaren!V19,2,1),IF(McLaren!V19,1,0))) -> 1
B21: Red Bracket 1 x 2 - 1 x 4 with Two Rounded Corners at the Bottom | E21: Trans-Red Tile, Modified 1 x 2 Grille with Bottom Groove / Lip | H21: Red Tile, Round 1 x 1 Quarter | K21: Red Tile, Modified 2 x 2 with Studs on Edge | N21: Red Slope, Curved 2 x 1 x 2/3 | Q21: Red Slope 45 2 x 1 with 2/3 Cutout | T21: Red Plate 1 x 4
B22: #VALUE! | C22: Nr. | D22: 6168619 | E22: #VALUE! | F22: Nr. | G22: 6250158 | H22: #VALUE! | I22: Nr. | J22: 6170390 | K22: #VALUE! | L22: Nr. | M22: 6219819 | N22: #VALUE! | O22: Nr. | P22: 6029946 | Q22: #VALUE! | R22: Nr. | S22: 6053011 | T22: #VALUE! | U22: Nr. | V22: 371021
C23: Gewicht | D23: 0.7817 | F23: Gewicht | G23: 0.2397 | I23: Gewicht | J23: 0.1071 | L23: Gewicht | M23: 0.5492 | O23: Gewicht | P23: 0.3011 | R23: Gewicht | S23: 0.4087 | U23: Gewicht | V23: 0.6503
C24: Anzahl | D24: =IF(Muscle_Car!D24,IF(Lamborghini!D24,IF(McLaren!D24,3,2),IF(McLaren!D24,2,1)),IF(Lamborghini!D24,IF(McLaren!D24,2,1),IF(McLaren!D24,1,0))) -> 1 | F24: Anzahl | G24: =IF(Muscle_Car!G24,IF(Lamborghini!G24,IF(McLaren!G24,3,2),IF(McLaren!G24,2,1)),IF(Lamborghini!G24,IF(McLaren!G24,2,1),IF(McLaren!G24,1,0))) -> 1 | I24: Anzahl | J24: =IF(Muscle_Car!J24,IF(Lamborghini!J24,IF(McLaren!J24,3,2),IF(McLaren!J24,2,1)),IF(Lamborghini!J24,IF(McLaren!J24,2,1),IF(McLaren!J24,1,0))) -> 1 | L24: Anzahl | M24: =IF(Muscle_Car!M24,IF(Lamborghini!M24,IF(McLaren!M24,3,2),IF(McLaren!M24,2,1)),IF(Lamborghini!M24,IF(McLaren!M24,2,1),IF(McLaren!M24,1,0))) -> 1 | O24: Anzahl | P24: =IF(Muscle_Car!P24,IF(Lamborghini!P24,IF(McLaren!P24,3,2),IF(McLaren!P24,2,1)),IF(Lamborghini!P24,IF(McLaren!P24,2,1),IF(McLaren!P24,1,0))) -> 1 | R24: Anzahl | S24: =IF(Muscle_Car!S24,IF(Lamborghini!S24,IF(McLaren!S24,3,2),IF(McLaren!S24,2,1)),IF(Lamborghini!S24,IF(McLaren!S24,2,1),IF(McLaren!S24,1,0))) -> 1 | U24: Anzahl | V24: =IF(Muscle_Car!V24,IF(Lamborghini!V24,IF(McLaren!V24,3,2),IF(McLaren!V24,2,1)),IF(Lamborghini!V24,IF(McLaren!V24,2,1),IF(McLaren!V24,1,0))) -> 1
B26: White Tile, Round 1 x 1 Half Circle Extended | E26: Light Bluish Gray Tile 1 x 1 with Groove | H26: Blue Wedge, Plate 2 x 2 Right | K26: Blue Wedge, Plate 2 x 2 Left | N26: Blue Tile 2 x 2 with Groove | Q26: Red Plate 1 x 2 | T26: Blue Wedge 2 x 1 x 2/3 Right
B27: #VALUE! | C27: Nr. | D27: 6131655 | E27: #VALUE! | F27: Nr. | G27: 4211415 | H27: #VALUE! | I27: Nr. | J27: 6189202 | K27: #VALUE! | L27: Nr. | M27: 6189198 | N27: #VALUE! | O27: Nr. | P27: 306823 | Q27: #VALUE! | R27: Nr. | S27: 302321 | T27: #VALUE! | U27: Nr. | V27: 6172411
C28: Gewicht | D28: 0.1257 | F28: Gewicht | G28: 0.1418 | I28: Gewicht | J28: 0.4511 | L28: Gewicht | M28: 0.4535 | O28: Gewicht | P28: 0.4796 | R28: Gewicht | S28: 0.3331 | U28: Gewicht | V28: 0.2242
C29: Anzahl | D29: =IF(Muscle_Car!D29,IF(Lamborghini!D29,IF(McLaren!D29,3,2),IF(McLaren!D29,2,1)),IF(Lamborghini!D29,IF(McLaren!D29,2,1),IF(McLaren!D29,1,0))) -> 1 | F29: Anzahl | G29: =IF(Muscle_Car!G29,IF(Lamborghini!G29,IF(McLaren!G29,3,2),IF(McLaren!G29,2,1)),IF(Lamborghini!G29,IF(McLaren!G29,2,1),IF(McLaren!G29,1,0))) -> 1 | I29: Anzahl | J29: =IF(Muscle_Car!J29,IF(Lamborghini!J29,IF(McLaren!J29,3,2),IF(McLaren!J29,2,1)),IF(Lamborghini!J29,IF(McLaren!J29,2,1),IF(McLaren!J29,1,0))) -> 1 | L29: Anzahl | M29: =IF(Muscle_Car!M29,IF(Lamborghini!M29,IF(McLaren!M29,3,2),IF(McLaren!M29,2,1)),IF(Lamborghini!M29,IF(McLaren!M29,2,1),IF(McLaren!M29,1,0))) -> 1 | O29: Anzahl | P29: =IF(Muscle_Car!P29,IF(Lamborghini!P29,IF(McLaren!P29,3,2),IF(McLaren!P29,2,1)),IF(Lamborghini!P29,IF(McLaren!P29,2,1),IF(McLaren!P29,1,0))) -> 1 | R29: Anzahl | S29: =IF(Muscle_Car!S29,IF(Lamborghini!S29,IF(McLaren!S29,3,2),IF(McLaren!S29,2,1)),IF(Lamborghini!S29,IF(McLaren!S29,2,1),IF(McLaren!S29,1,0))) -> 1 | U29: Anzahl | V29: =IF(Muscle_Car!V29,IF(Lamborghini!V29,IF(McLaren!V29,3,2),IF(McLaren!V29,2,1)),IF(Lamborghini!V29,IF(McLaren!V29,2,1),IF(McLaren!V29,1,0))) -> 1
B31: Blue Tile 1 x 2 with Groove | E31: Blue Plate 1 x 10 | H31: Black Tile, Modified 1 x 2 Grille with Bottom Groove / Lip | K31: Black Tile, 1 x 4 | N31: Red Slope, Curved 4 x 2 | Q31: Red Vehicla, Mudguard 2 x 4 with Arch Studded with Hole | T31: Red Wedge 3 x 4 x 2/3 Curved with Cutout
B32: #VALUE! | C32: Nr. | D32: 306923 | E32: #VALUE! | F32: Nr. | G32: 447723 | H32: #VALUE! | I32: Nr. | J32: 241226 | K32: #VALUE! | L32: Nr. | M32: 243126 | N32: #VALUE! | O32: Nr. | P32: 4613174 | Q32: #VALUE! | R32: Nr. | S32: 4518231 | T32: #VALUE! | U32: Nr. | V32: 6179656
C33: Gewicht | D33: 0.2575 | F33: Gewicht | G33: 1.6056 | I33: Gewicht | J33: 0.2158 | L33: Gewicht | M33: 0.5271 | O33: Gewicht | P33: 1.3333 | R33: Gewicht | S33: 1.3094 | U33: Gewicht | V33: 1.4239
C34: Anzahl | D34: =IF(Muscle_Car!D34,IF(Lamborghini!D34,IF(McLaren!D34,3,2),IF(McLaren!D34,2,1)),IF(Lamborghini!D34,IF(McLaren!D34,2,1),IF(McLaren!D34,1,0))) -> 1 | F34: Anzahl | G34: =IF(Muscle_Car!G34,IF(Lamborghini!G34,IF(McLaren!G34,3,2),IF(McLaren!G34,2,1)),IF(Lamborghini!G34,IF(McLaren!G34,2,1),IF(McLaren!G34,1,0))) -> 1 | I34: Anzahl | J34: =IF(Muscle_Car!J34,IF(Lamborghini!J34,IF(McLaren!J34,3,2),IF(McLaren!J34,2,1)),IF(Lamborghini!J34,IF(McLaren!J34,2,1),IF(McLaren!J34,1,0))) -> 1 | L34: Anzahl | M34: =IF(Muscle_Car!M34,IF(Lamborghini!M34,IF(McLaren!M34,3,2),IF(McLaren!M34,2,1)),IF(Lamborghini!M34,IF(McLaren!M34,2,1),IF(McLaren!M34,1,0))) -> 2 | O34: Anzahl | P34: =IF(Muscle_Car!P34,IF(Lamborghini!P34,IF(McLaren!P34,3,2),IF(McLaren!P34,2,1)),IF(Lamborghini!P34,IF(McLaren!P34,2,1),IF(McLaren!P34,1,0))) -> 1 | R34: Anzahl | S34: =IF(Muscle_Car!S34,IF(Lamborghini!S34,IF(McLaren!S34,3,2),IF(McLaren!S34,2,1)),IF(Lamborghini!S34,IF(McLaren!S34,2,1),IF(McLaren!S34,1,0))) -> 1 | U34: Anzahl | V34: =IF(Muscle_Car!V34,IF(Lamborghini!V34,IF(McLaren!V34,3,2),IF(McLaren!V34,2,1)),IF(Lamborghini!V34,IF(McLaren!V34,2,1),IF(McLaren!V34,1,0))) -> 1
B36: Lagerbock 100-000-001 | E36: Sicherungsring DIN 471 - 1,0 x 1,0 | H36: Sicherungsring DIN 472 - 30 x 1,2 | K36: Rillenkugellager DIN 625 - 6200 - P2 | N36: Gewindestift ISO 4027 - M4 x 6 - A5 - 45H | Q36: Black Plate 2 x 3 | T36: Black Brick, Modified 1 x 1 with Stud on Side
B37: #VALUE! | C37: Nr. | D37: L007001 | E37: #VALUE! | F37: Nr. | G37: L007002 | H37: #VALUE! | I37: Nr. | J37: L007003 | K37: #VALUE! | L37: Nr. | M37: L007004 | N37: #VALUE! | O37: Nr. | P37: L007005 | Q37: #VALUE! | R37: Nr. | S37: 302126 | T37: #VALUE! | U37: Nr. | V37: 4558954
C38: Gewicht | D38: 8.88 | F38: Gewicht | G38: 0.405 | I38: Gewicht | J38: 1.9188 | L38: Gewicht | M38: 30.775 | O38: Gewicht | P38: 0.2825 | R38: Gewicht | S38: 0.8589 | U38: Gewicht | V38: 0.4278
C39: Anzahl | D39: =IF(Muscle_Car!D39,IF(Lamborghini!D39,IF(McLaren!D39,3,2),IF(McLaren!D39,2,1)),IF(Lamborghini!D39,IF(McLaren!D39,2,1),IF(McLaren!D39,1,0))) -> 0 | F39: Anzahl | G39: =IF(Muscle_Car!G39,IF(Lamborghini!G39,IF(McLaren!G39,3,2),IF(McLaren!G39,2,1)),IF(Lamborghini!G39,IF(McLaren!G39,2,1),IF(McLaren!G39,1,0))) -> 0 | I39: Anzahl | J39: =IF(Muscle_Car!J39,IF(Lamborghini!J39,IF(McLaren!J39,3,2),IF(McLaren!J39,2,1)),IF(Lamborghini!J39,IF(McLaren!J39,2,1),IF(McLaren!J39,1,0))) -> 0 | L39: Anzahl | M39: =IF(Muscle_Car!M39,IF(Lamborghini!M39,IF(McLaren!M39,3,2),IF(McLaren!M39,2,1)),IF(Lamborghini!M39,IF(McLaren!M39,2,1),IF(McLaren!M39,1,0))) -> 0 | O39: Anzahl | P39: =IF(Muscle_Car!P39,IF(Lamborghini!P39,IF(McLaren!P39,3,2),IF(McLaren!P39,2,1)),IF(Lamborghini!P39,IF(McLaren!P39,2,1),IF(McLaren!P39,1,0))) -> 0 | R39: Anzahl | S39: =IF(Muscle_Car!S39,IF(Lamborghini!S39,IF(McLaren!S39,3,2),IF(McLaren!S39,2,1)),IF(Lamborghini!S39,IF(McLaren!S39,2,1),IF(McLaren!S39,1,0))) -> 1 | U39: Anzahl | V39: =IF(Muscle_Car!V39,IF(Lamborghini!V39,IF(McLaren!V39,3,2),IF(McLaren!V39,2,1)),IF(Lamborghini!V39,IF(McLaren!V39,2,1),IF(McLaren!V39,1,0))) -> 1
B42: Rechte Seite
B44: Black Bracket 1 x 2 - 1 x 4 with Two Rounded Corners at the Bottom | E44: Black Bracket 1 x 2 - 2 x 2 | H44: Black Plate 1 x 1 | K44: Part 54200 Slope 30 1 x 1 x 2/3 | N44: Dark Orange Plate Round 1 x 1 | Q44: Black Panel 1 x 1 x 1 Corner | T44: Red Plate 1 x 1
B45: #VALUE! | C45: Nr. | D45: 6168620 | E45: #VALUE! | F45: Nr. | G45: 6117973 | H45: #VALUE! | I45: Nr. | J45: 302426 | K45: #VALUE! | L45: Nr. | M45: 4287159 | N45: #VALUE! | O45: Nr. | P45: 6315782 | Q45: #VALUE! | R45: Nr. | S45: 4106347 | T45: #VALUE! | U45: Nr. | V45: 302421
C46: Gewicht | D46: 0.7731 | F46: Gewicht | G46: 0.7924 | I46: Gewicht | J46: 0.1745 | L46: Gewicht | M46: 0.1848 | O46: Gewicht | P46: 0.1043 | R46: Gewicht | S46: 0.2889 | U46: Gewicht | V46: 0.175
